Workbook

Sheet New report
A1: Perdiem Report in March 2020
A2: Item | B2: AllStar ID | C2: Name - Surname | D2: 43891 | AI2: Count Day | AJ2: Total Perdiem (THB) | AL2: Cross Checked by Supervisor | AM2: REMARK
D3: 1 | E3: 2 | F3: 3 | G3: 4 | H3: 5 | I3: 6 | J3: 7 | K3: 8 | L3: 9 | M3: 10 | N3: 11 | O3: 12 | P3: 13 | Q3: 14 | R3: 15 | S3: 16 | T3: 17 | U3: 18 | V3: 19 | W3: 20 | X3: 21 | Y3: 22 | Z3: 23 | AA3: 24 | AB3: 25 | AC3: 26 | AD3: 27 | AE3: 28 | AF3: 29 | AG3: 30 | AH3: 31 | AK3: Dupplicate Check
A4: 1 | C4: =iferror(vlookup(B4,'Crew Data'!C:G,5,0)," ") | D4: FALSE | E4: FALSE | F4: FALSE | G4: FALSE | H4: FALSE | I4: FALSE | J4: FALSE | K4: FALSE | L4: FALSE | M4: FALSE | N4: FALSE | O4: FALSE | P4: FALSE | Q4: FALSE | R4: FALSE | S4: FALSE | T4: FALSE | U4: FALSE | V4: FALSE | W4: FALSE | X4: FALSE | Y4: FALSE | Z4: FALSE | AA4: FALSE | AB4: FALSE | AC4: FALSE | AD4: FALSE | AE4: FALSE | AF4: FALSE | AG4: FALSE | AH4: FALSE | AI4: =countif(D4:AH4,"True") -> 0 | AJ4: =AI4*400 -> 0 | AK4: =COUNTIF(B:B,B4) -> 0
A5: 2 | C5: =iferror(vlookup(B5,'Crew Data'!C:G,5,0)," ") | D5: FALSE | E5: FALSE | F5: FALSE | G5: FALSE | H5: FALSE | I5: FALSE | J5: FALSE | K5: FALSE | L5: FALSE | M5: FALSE | N5: FALSE | O5: FALSE | P5: FALSE | Q5: FALSE | R5: FALSE | S5: FALSE | T5: FALSE | U5: FALSE | V5: FALSE | W5: FALSE | X5: FALSE | Y5: FALSE | Z5: FALSE | AA5: FALSE | AB5: FALSE | AC5: FALSE | AD5: FALSE | AE5: FALSE | AF5: FALSE | AG5: FALSE | AH5: FALSE | AI5: =countif(D5:AH5,"True") -> 0 | AJ5: =AI5*400 -> 0 | AK5: =COUNTIF(B:B,B5) -> 0
A6: 3 | C6: =iferror(vlookup(B6,'Crew Data'!C:G,5,0)," ") | D6: FALSE | E6: FALSE | F6: FALSE | G6: FALSE | H6: FALSE | I6: FALSE | J6: FALSE | K6: FALSE | L6: FALSE | M6: FALSE | N6: FALSE | O6: FALSE | P6: FALSE | Q6: FALSE | R6: FALSE | S6: FALSE | T6: FALSE | U6: FALSE | V6: FALSE | W6: FALSE | X6: FALSE | Y6: FALSE | Z6: FALSE | AA6: FALSE | AB6: FALSE | AC6: FALSE | AD6: FALSE | AE6: FALSE | AF6: FALSE | AG6: FALSE | AH6: FALSE | AI6: =countif(D6:AH6,"True") -> 0 | AJ6: =AI6*400 -> 0 | AK6: =COUNTIF(B:B,B6) -> 0
A7: 4 | C7: =iferror(vlookup(B7,'Crew Data'!C:G,5,0)," ") | D7: FALSE | E7: FALSE | F7: FALSE | G7: FALSE | H7: FALSE | I7: FALSE | J7: FALSE | K7: FALSE | L7: FALSE | M7: FALSE | N7: FALSE | O7: FALSE | P7: FALSE | Q7: FALSE | R7: FALSE | S7: FALSE | T7: FALSE | U7: FALSE | V7: FALSE | W7: FALSE | X7: FALSE | Y7: FALSE | Z7: FALSE | AA7: FALSE | AB7: FALSE | AC7: FALSE | AD7: FALSE | AE7: FALSE | AF7: FALSE | AG7: FALSE | AH7: FALSE | AI7: =countif(D7:AH7,"True") -> 0 | AJ7: =AI7*400 -> 0 | AK7: =COUNTIF(B:B,B7) -> 0
A8: 5 | C8: =iferror(vlookup(B8,'Crew Data'!C:G,5,0)," ") | D8: FALSE | E8: FALSE | F8: FALSE | G8: FALSE | H8: FALSE | I8: FALSE | J8: FALSE | K8: FALSE | L8: FALSE | M8: FALSE | N8: FALSE | O8: FALSE | P8: FALSE | Q8: FALSE | R8: FALSE | S8: FALSE | T8: FALSE | U8: FALSE | V8: FALSE | W8: FALSE | X8: FALSE | Y8: FALSE | Z8: FALSE | AA8: FALSE | AB8: FALSE | AC8: FALSE | AD8: FALSE | AE8: FALSE | AF8: FALSE | AG8: FALSE | AH8: FALSE | AI8: =countif(D8:AH8,"True") -> 0 | AJ8: =AI8*400 -> 0 | AK8: =COUNTIF(B:B,B8) -> 0
A9: 6 | C9: =iferror(vlookup(B9,'Crew Data'!C:G,5,0)," ") | D9: FALSE | E9: FALSE | F9: FALSE | G9: FALSE | H9: FALSE | I9: FALSE | J9: FALSE | K9: FALSE | L9: FALSE | M9: FALSE | N9: FALSE | O9: FALSE | P9: FALSE | Q9: FALSE | R9: FALSE | S9: FALSE | T9: FALSE | U9: FALSE | V9: FALSE | W9: FALSE | X9: FALSE | Y9: FALSE | Z9: FALSE | AA9: FALSE | AB9: FALSE | AC9: FALSE | AD9: FALSE | AE9: FALSE | AF9: FALSE | AG9: FALSE | AH9: FALSE | AI9: =countif(D9:AH9,"True") -> 0 | AJ9: =AI9*400 -> 0 | AK9: =COUNTIF(B:B,B9) -> 0
A10: 7 | C10: =iferror(vlookup(B10,'Crew Data'!C:G,5,0)," ") | D10: FALSE | E10: FALSE | F10: FALSE | G10: FALSE | H10: FALSE | I10: FALSE | J10: FALSE | K10: FALSE | L10: FALSE | M10: FALSE | N10: FALSE | O10: FALSE | P10: FALSE | Q10: FALSE | R10: FALSE | S10: FALSE | T10: FALSE | U10: FALSE | V10: FALSE | W10: FALSE | X10: FALSE | Y10: FALSE | Z10: FALSE | AA10: FALSE | AB10: FALSE | AC10: FALSE | AD10: FALSE | AE10: FALSE | AF10: FALSE | AG10: FALSE | AH10: FALSE | AI10: =countif(D10:AH10,"True") -> 0 | AJ10: =AI10*400 -> 0 | AK10: =COUNTIF(B:B,B10) -> 0
A11: 8 | C11: =iferror(vlookup(B11,'Crew Data'!C:G,5,0)," ") | D11: FALSE | E11: FALSE | F11: FALSE | G11: FALSE | H11: FALSE | I11: FALSE | J11: FALSE | K11: FALSE | L11: FALSE | M11: FALSE | N11: FALSE | O11: FALSE | P11: FALSE | Q11: FALSE | R11: FALSE | S11: FALSE | T11: FALSE | U11: FALSE | V11: FALSE | W11: FALSE | X11: FALSE | Y11: FALSE | Z11: FALSE | AA11: FALSE | AB11: FALSE | AC11: FALSE | AD11: FALSE | AE11: FALSE | AF11: FALSE | AG11: FALSE | AH11: FALSE | AI11: =countif(D11:AH11,"True") -> 0 | AJ11: =AI11*400 -> 0 | AK11: =COUNTIF(B:B,B11) -> 0
A12: 9 | C12: =iferror(vlookup(B12,'Crew Data'!C:G,5,0)," ") | D12: FALSE | E12: FALSE | F12: FALSE | G12: FALSE | H12: FALSE | I12: FALSE | J12: FALSE | K12: FALSE | L12: FALSE | M12: FALSE | N12: FALSE | O12: FALSE | P12: FALSE | Q12: FALSE | R12: FALSE | S12: FALSE | T12: FALSE | U12: FALSE | V12: FALSE | W12: FALSE | X12: FALSE | Y12: FALSE | Z12: FALSE | AA12: FALSE | AB12: FALSE | AC12: FALSE | AD12: FALSE | AE12: FALSE | AF12: FALSE | AG12: FALSE | AH12: FALSE | AI12: =countif(D12:AH12,"True") -> 0 | AJ12: =AI12*400 -> 0 | AK12: =COUNTIF(B:B,B12) -> 0
A13: 10 | C13: =iferror(vlookup(B13,'Crew Data'!C:G,5,0)," ") | D13: FALSE | E13: FALSE | F13: FALSE | G13: FALSE | H13: FALSE | I13: FALSE | J13: FALSE | K13: FALSE | L13: FALSE | M13: FALSE | N13: FALSE | O13: FALSE | P13: FALSE | Q13: FALSE | R13: FALSE | S13: FALSE | T13: FALSE | U13: FALSE | V13: FALSE | W13: FALSE | X13: FALSE | Y13: FALSE | Z13: FALSE | AA13: FALSE | AB13: FALSE | AC13: FALSE | AD13: FALSE | AE13: FALSE | AF13: FALSE | AG13: FALSE | AH13: FALSE | AI13: =countif(D13:AH13,"True") -> 0 | AJ13: =AI13*400 -> 0 | AK13: =COUNTIF(B:B,B13) -> 0
A14: 11 | C14: =iferror(vlookup(B14,'Crew Data'!C:G,5,0)," ") | D14: FALSE | E14: FALSE | F14: FALSE | G14: FALSE | H14: FALSE | I14: FALSE | J14: FALSE | K14: FALSE | L14: FALSE | M14: FALSE | N14: FALSE | O14: FALSE | P14: FALSE | Q14: FALSE | R14: FALSE | S14: FALSE | T14: FALSE | U14: FALSE | V14: FALSE | W14: FALSE | X14: FALSE | Y14: FALSE | Z14: FALSE | AA14: FALSE | AB14: FALSE | AC14: FALSE | AD14: FALSE | AE14: FALSE | AF14: FALSE | AG14: FALSE | AH14: FALSE | AI14: =countif(D14:AH14,"True") -> 0 | AJ14: =AI14*400 -> 0 | AK14: =COUNTIF(B:B,B14) -> 0
A15: 12 | C15: =iferror(vlookup(B15,'Crew Data'!C:G,5,0)," ") | D15: FALSE | E15: FALSE | F15: FALSE | G15: FALSE | H15: FALSE | I15: FALSE | J15: FALSE | K15: FALSE | L15: FALSE | M15: FALSE | N15: FALSE | O15: FALSE | P15: FALSE | Q15: FALSE | R15: FALSE | S15: FALSE | T15: FALSE | U15: FALSE | V15: FALSE | W15: FALSE | X15: FALSE | Y15: FALSE | Z15: FALSE | AA15: FALSE | AB15: FALSE | AC15: FALSE | AD15: FALSE | AE15: FALSE | AF15: FALSE | AG15: FALSE | AH15: FALSE | AI15: =countif(D15:AH15,"True") -> 0 | AJ15: =AI15*400 -> 0 | AK15: =COUNTIF(B:B,B15) -> 0
... A148: 145 | C148: =iferror(vlookup(B148,'Crew Data'!C:G,5,0)," ") | D148: FALSE | E148: FALSE | F148: FALSE | G148: FALSE | H148: FALSE | I148: FALSE | J148: FALSE | K148: FALSE | L148: FALSE | M148: FALSE | N148: FALSE | O148: FALSE | P148: FALSE | Q148: FALSE | R148: FALSE | S148: FALSE | T148: FALSE | U148: FALSE | V148: FALSE | W148: FALSE | X148: FALSE | Y148: FALSE | Z148: FALSE | AA148: FALSE | AB148: FALSE | AC148: FALSE | AD148: FALSE | AE148: FALSE | AF148: FALSE | AG148: FALSE | AH148: FALSE | AI148: =countif(D148:AH148,"True") -> 0 | AJ148: =AI148*400 -> 0 | AK148: =COUNTIF(B:B,B148) -> 0

Sheet DECEMBER 21
A1: Perdiem Report in December 2021 | H1: Last updated : 1 January 2022 Time: 12.00 (Status : CLOSE)
A2: Item | B2: New ID No. | C2: Employee name | D2: Period | E2: Description
E3: Days | F3: Total Perdiem (THB) | H3: Cross Checked by Supervisor | I3: REMARK
C4: =vlookup(B4,'Crew Data'!C:G,5,0) -> #N/A | F4: =E4*400 -> 0 | G4: =COUNTIF(B:B,B4) -> 0
A7: ไม่มีการทำจ่ายเงินค่า Posting

Sheet MARCH 23
A1: Perdiem Report in MARCH 2023 | H1: Last updated : 03 April 2023 Time: 12.00 (Status : CLOSE)
A2: Item | B2: New ID No. | C2: Employee name | D2: Period | E2: Description
E3: Days | F3: Total Perdiem (THB) | H3: Cross Checked by Supervisor | I3: REMARK
A4: 1 | B4: 1000732 | C4: =vlookup(B4,'Crew Data'!C:G,5,0) -> Inthra Mathiang | D4: 25-27 March 2023 | E4: 3 | F4: =E4*400 -> 1200 | G4: =COUNTIF(B:B,B4) -> 1 | H4: CHECKED (OK)
A5: 2 | B5: 1011507 | C5: =vlookup(B5,'Crew Data'!C:G,5,0) -> Weerinpimon Rhuecharoen | D5: 25-27 March 2023 | E5: 3 | F5: =E5*400 -> 1200 | G5: =COUNTIF(B:B,B5) -> 1 | H5: CHECKED (OK)
A6: 3 | B6: 1010890 | C6: =vlookup(B6,'Crew Data'!C:G,5,0) -> Keetawan Udomkiattikul | D6: 25-27 March 2023 | E6: 3 | F6: =E6*400 -> 1200 | G6: =COUNTIF(B:B,B6) -> 1 | H6: CHECKED (OK)
A7: 4 | B7: 1006747 | C7: =vlookup(B7,'Crew Data'!C:G,5,0) -> Phichayanat Duangprasanchai | D7: 26-28 March 2023 | E7: 3 | F7: =E7*400 -> 1200 | G7: =COUNTIF(B:B,B7) -> 1 | H7: CHECKED (OK)
A8: 5 | B8: 1007011 | C8: =vlookup(B8,'Crew Data'!C:G,5,0) -> Jeeraprapa Tuptimdang | D8: 27-29 March 2023 | E8: 3 | F8: =E8*400 -> 1200 | G8: =COUNTIF(B:B,B8) -> 1 | H8: CHECKED (OK)
A9: 6 | B9: 1007020 | C9: =vlookup(B9,'Crew Data'!C:G,5,0) -> Thamonwan Chinnarukbumrung | D9: 27-29 March 2023 | E9: 3 | F9: =E9*400 -> 1200 | G9: =COUNTIF(B:B,B9) -> 1 | H9: CHECKED (OK)
A10: 7 | B10: 1012899 | C10: =vlookup(B10,'Crew Data'!C:G,5,0) -> Pichaya Sonthigorn | D10: 25-27 March 2023 | E10: 3 | F10: =E10*400 -> 1200 | G10: =COUNTIF(B:B,B10) -> 1 | H10: CHECKED (OK)
A11: 8 | B11: 1018791 | C11: =vlookup(B11,'Crew Data'!C:G,5,0) -> Kitdanai Tiantanawit | D11: 26-28 March 2023 | E11: 3 | F11: =E11*400 -> 1200 | G11: =COUNTIF(B:B,B11) -> 1 | H11: CHECKED (OK)
A12: 9 | B12: 1007017 | C12: =vlookup(B12,'Crew Data'!C:G,5,0) -> #N/A | D12: 26-28 March 2023 | E12: 3 | F12: =E12*400 -> 1200 | G12: =COUNTIF(B:B,B12) -> 1 | H12: CHECKED (OK)
A13: 10 | B13: 1018807 | C13: =vlookup(B13,'Crew Data'!C:G,5,0) -> Prapassorn Soonsorn | D13: 27-29 March 2023 | E13: 3 | F13: =E13*400 -> 1200 | G13: =COUNTIF(B:B,B13) -> 1 | H13: CHECKED (OK)
A14: 11 | B14: 1025318 | C14: =vlookup(B14,'Crew Data'!C:G,5,0) -> Jetsada Sutthiniam | D14: 28-30 March 2023 | E14: 3 | F14: =E14*400 -> 1200 | G14: =COUNTIF(B:B,B14) -> 1 | H14: CHECKED (OK)
A15: 12 | B15: 1006352 | C15: =vlookup(B15,'Crew Data'!C:G,5,0) -> Sirinthip Singhadecha | D15: 27-29 March 2023 | E15: 3 | F15: =E15*400 -> 1200 | G15: =COUNTIF(B:B,B15) -> 1 | H15: CHECKED (OK)
... A23: 20 | B23: 1007016 | C23: =vlookup(B23,'Crew Data'!C:G,5,0) -> Sathita Pongsomran | D23: 26-28 March 2023 | E23: 3 | F23: =E23*400 -> 1200 | G23: =COUNTIF(B:B,B23) -> 1 | H23: CHECKED (OK)
A24: END OF REPORT 4 APRIL 2023

Sheet APRIL 23
A1: Perdiem Report in APRIL 2023 | H1: Last updated : 02 May 2023 Time: 17.00 (Status : CLOSE)
A2: Item | B2: New ID No. | C2: Employee name | D2: Period | E2: Description
E3: Days | F3: Total Perdiem (THB) | H3: Cross Checked by Supervisor | I3: REMARK
A4: 1 | B4: 1003385 | C4: =vlookup(B4,'Crew Data'!C:G,5,0) -> Jaruma Jantarapap | D4: 3-4 April 2023 | E4: 2 | F4: =E4*400 -> 800 | G4: =COUNTIF(B:B,B4) -> 1 | H4: CHECKED (OK)
A5: 2 | B5: 1004213 | C5: =vlookup(B5,'Crew Data'!C:G,5,0) -> Worapada Suetrongmunkong | D5: 8-9 April 2023 | E5: 2 | F5: =E5*400 -> 800 | G5: =COUNTIF(B:B,B5) -> 1 | H5: CHECKED (OK)
A6: 3 | B6: 1022989 | C6: =vlookup(B6,'Crew Data'!C:G,5,0) -> Peeranat Chavitranurak | D6: 7-8 April 2023 | E6: 2 | F6: =E6*400 -> 800 | G6: =COUNTIF(B:B,B6) -> 1 | H6: CHECKED (OK)
A7: 4 | B7: 1005287 | C7: =vlookup(B7,'Crew Data'!C:G,5,0) -> Thanawan Seemakul | D7: 8-9 April 2023 | E7: 2 | F7: =E7*400 -> 800 | G7: =COUNTIF(B:B,B7) -> 1 | H7: CHECKED (OK)
A8: 5 | B8: 1022660 | C8: =vlookup(B8,'Crew Data'!C:G,5,0) -> Ketjiya Sriamonsak | D8: 9-10 April 2023 | E8: 2 | F8: =E8*400 -> 800 | G8: =COUNTIF(B:B,B8) -> 1 | H8: CHECKED (OK)
A9: 6 | B9: 1007416 | C9: =vlookup(B9,'Crew Data'!C:G,5,0) -> Metus Leearporn | D9: 2-3 April 2023 | E9: 2 | F9: =E9*400 -> 800 | G9: =COUNTIF(B:B,B9) -> 1 | H9: CHECKED (OK)
A10: 7 | B10: 1007277 | C10: =vlookup(B10,'Crew Data'!C:G,5,0) -> Theerapat Sudsawas | D10: 2-3 April 2023 | E10: 2 | F10: =E10*400 -> 800 | G10: =COUNTIF(B:B,B10) -> 1 | H10: CHECKED (OK)
A11: 8 | B11: 1018803 | C11: =vlookup(B11,'Crew Data'!C:G,5,0) -> Natthaphon Poosomchit | D11: 3-4, 10-11 April 2023 | E11: 4 | F11: =E11*400 -> 1600 | G11: =COUNTIF(B:B,B11) -> 1 | H11: CHECKED (OK)
A12: 9 | B12: 1003386 | C12: =vlookup(B12,'Crew Data'!C:G,5,0) -> #N/A | D12: 11-12 April 2023 | E12: 2 | F12: =E12*400 -> 800 | G12: =COUNTIF(B:B,B12) -> 1 | H12: CHECKED (OK)
A13: 10 | B13: 1003384 | C13: =vlookup(B13,'Crew Data'!C:G,5,0) -> Chatchaya Bhoocharyarth | D13: 6-7 April 2023 | E13: 2 | F13: =E13*400 -> 800 | G13: =COUNTIF(B:B,B13) -> 1 | H13: CHECKED (OK)
A14: 11 | B14: 1001818 | C14: =vlookup(B14,'Crew Data'!C:G,5,0) -> Tanyapat Limthananat | D14: 14-15 April 2023 | E14: 2 | F14: =E14*400 -> 800 | G14: =COUNTIF(B:B,B14) -> 1 | H14: CHECKED (OK)
A15: 12 | B15: 1017926 | C15: =vlookup(B15,'Crew Data'!C:G,5,0) -> Noppamanee Samranrat | D15: 4-5 April 2023 | E15: 2 | F15: =E15*400 -> 800 | G15: =COUNTIF(B:B,B15) -> 1 | H15: CHECKED (OK)
... A84: 81 | B84: 1007153 | C84: =vlookup(B84,'Crew Data'!C:G,5,0) -> Pannathat Chuchuaisuwan | D84: 8-9, 18-19, 30 April / 1 May 2023 | E84: 6 | F84: =E84*400 -> 2400 | G84: =COUNTIF(B:B,B84) -> 1 | H84: CHECKED (OK)

Sheet JUNE 23
A1: Perdiem Report in JUNE 2023 | H1: Last updated : 03 JULY 2023 Time: 12.00 (Status : CLOSE)
A2: Item | B2: New ID No. | C2: Employee name | D2: Period | E2: Description
E3: Days | F3: Total Perdiem (THB) | H3: Cross Checked by Supervisor | I3: REMARK
A4: 1 | B4: 1022858 | C4: =vlookup(B4,'Crew Data'!C:G,5,0) -> Methakarn Ratanamalaya | D4: 14-15 May 2023 | E4: 2 | F4: =E4*400 -> 800 | G4: =COUNTIF(B:B,B4) -> 1 | H4: CHECKED (OK)
A5: 2 | B5: 1002986 | C5: =vlookup(B5,'Crew Data'!C:G,5,0) -> Sirikhwan Siringoen | D5: 9-10 June 2023 | E5: 2 | F5: =E5*400 -> 800 | G5: =COUNTIF(B:B,B5) -> 1 | H5: CHECKED (OK)
A6: 3 | B6: 1008894 | C6: =vlookup(B6,'Crew Data'!C:G,5,0) -> Piyaphong Hongsiri | D6: 9-10 June 2023 | E6: 2 | F6: =E6*400 -> 800 | G6: =COUNTIF(B:B,B6) -> 1 | H6: CHECKED (OK)
A7: 4 | B7: 1007153 | C7: =vlookup(B7,'Crew Data'!C:G,5,0) -> Pannathat Chuchuaisuwan | D7: 5-6 June 2023 | E7: 2 | F7: =E7*400 -> 800 | G7: =COUNTIF(B:B,B7) -> 1 | H7: CHECKED (OK)
A8: 5 | B8: 1007034 | C8: =vlookup(B8,'Crew Data'!C:G,5,0) -> Raveekankate Sukasemthongdi | D8: 9-10 June 2023 | E8: 2 | F8: =E8*400 -> 800 | G8: =COUNTIF(B:B,B8) -> 1 | H8: CHECKED (OK)
A9: 6 | B9: 1007157 | C9: =vlookup(B9,'Crew Data'!C:G,5,0) -> Pichanun Seneetantikul | D9: 5-6 June 2023 | E9: 2 | F9: =E9*400 -> 800 | G9: =COUNTIF(B:B,B9) -> 1 | H9: CHECKED (OK)
A10: 7 | B10: 1005443 | C10: =vlookup(B10,'Crew Data'!C:G,5,0) -> Pipassa Laopiyasakul | D10: 6-7 June 2023 | E10: 2 | F10: =E10*400 -> 800 | G10: =COUNTIF(B:B,B10) -> 1 | H10: CHECKED (OK)
A11: 8 | B11: 1007161 | C11: =vlookup(B11,'Crew Data'!C:G,5,0) -> Prangnaree Sahawatcharin | D11: 5-6 June 2023 | E11: 2 | F11: =E11*400 -> 800 | G11: =COUNTIF(B:B,B11) -> 1 | H11: CHECKED (OK)
A12: 9 | B12: 1002202 | C12: =vlookup(B12,'Crew Data'!C:G,5,0) -> Nithipkan Damrongpongkhajorn | D12: 1-2 June 2023 | E12: 2 | F12: =E12*400 -> 800 | G12: =COUNTIF(B:B,B12) -> 1 | H12: CHECKED (OK)
A13: 10 | B13: 1009818 | C13: =vlookup(B13,'Crew Data'!C:G,5,0) -> #N/A | D13: 2-3 June 2023 | E13: 2 | F13: =E13*400 -> 800 | G13: =COUNTIF(B:B,B13) -> 1 | H13: CHECKED (OK)
A14: 11 | B14: 1005306 | C14: =vlookup(B14,'Crew Data'!C:G,5,0) -> Sirirat Kaewduangkhae | D14: 4-5 June 2023 | E14: 2 | F14: =E14*400 -> 800 | G14: =COUNTIF(B:B,B14) -> 1 | H14: CHECKED (OK)
A15: 12 | B15: 1001273 | C15: =vlookup(B15,'Crew Data'!C:G,5,0) -> Chidchanok Seesorn | D15: 9-10 June 2023 | E15: 2 | F15: =E15*400 -> 800 | G15: =COUNTIF(B:B,B15) -> 1 | H15: CHECKED (OK)
... A100: 97 | B100: 1017657 | C100: =vlookup(B100,'Crew Data'!C:G,5,0) -> Yanakorn Charnfun | D100: 5-6 June 2023 | E100: 2 | F100: =E100*400 -> 800 | G100: =COUNTIF(B:B,B100) -> 1 | H100: CHECKED (OK)

Sheet AUGUST 23
A1: Perdiem Report in AUGUST 2023 | H1: Last updated : 04 SEPTEMBER 2023 Time: 12.00 (Status : CLOSE)
A2: Item | B2: New ID No. | C2: Employee name | D2: Period | E2: Description
E3: Days | F3: Total Perdiem (THB) | H3: Cross Checked by Supervisor | I3: REMARK
A4: 1 | B4: 1010731 | C4: =vlookup(B4,'Crew Data'!C:G,5,0) -> Samatikan Boonket | D4: 26-27 July 2023 | E4: 2 | F4: =E4*400 -> 800 | G4: =COUNTIF(B:B,B4) -> 1 | H4: CHECKED (OK)
A5: 2 | B5: 1012372 | C5: =vlookup(B5,'Crew Data'!C:G,5,0) -> Vinida Ma | D5: 1-2 August 2023 | E5: 2 | F5: =E5*400 -> 800 | G5: =COUNTIF(B:B,B5) -> 1 | H5: CHECKED (OK)
A6: 3 | B6: 1000736 | C6: =vlookup(B6,'Crew Data'!C:G,5,0) -> Ekkachai Moolla | D6: 1-2 August 2023 | E6: 2 | F6: =E6*400 -> 800 | G6: =COUNTIF(B:B,B6) -> 1 | H6: CHECKED (OK)
A7: 4 | B7: 1004583 | C7: =vlookup(B7,'Crew Data'!C:G,5,0) -> Suphanun Yotpunya | D7: 6-7 June 2023 | E7: 2 | F7: =E7*400 -> 800 | G7: =COUNTIF(B:B,B7) -> 1 | H7: CHECKED (OK)
A8: 5 | B8: 1005287 | C8: =vlookup(B8,'Crew Data'!C:G,5,0) -> Thanawan Seemakul | D8: 5-6 July 2023 | E8: 2 | F8: =E8*400 -> 800 | G8: =COUNTIF(B:B,B8) -> 1 | H8: CHECKED (OK)
A9: 6 | B9: 1002202 | C9: =vlookup(B9,'Crew Data'!C:G,5,0) -> Nithipkan Damrongpongkhajorn | D9: 2-3 August 2023 | E9: 2 | F9: =E9*400 -> 800 | G9: =COUNTIF(B:B,B9) -> 1 | H9: CHECKED (OK)
A10: 7 | B10: 1012984 | C10: =vlookup(B10,'Crew Data'!C:G,5,0) -> Issaree Opasvimud | D10: 3-4 August 2023 | E10: 2 | F10: =E10*400 -> 800 | G10: =COUNTIF(B:B,B10) -> 1 | H10: CHECKED (OK)
A11: 8 | B11: 1023582 | C11: =vlookup(B11,'Crew Data'!C:G,5,0) -> Rawiwan Chailerst | D11: 3-4 August 2023 | E11: 2 | F11: =E11*400 -> 800 | G11: =COUNTIF(B:B,B11) -> 1 | H11: CHECKED (OK)
A12: 9 | B12: 1007003 | C12: =vlookup(B12,'Crew Data'!C:G,5,0) -> Ravipa Tumsen | D12: 5-6 August 2023 | E12: 2 | F12: =E12*400 -> 800 | G12: =COUNTIF(B:B,B12) -> 1 | H12: CHECKED (OK)
A13: 10 | B13: 1006989 | C13: =vlookup(B13,'Crew Data'!C:G,5,0) -> Pimlawee Unn-A-Nant | D13: 5-6 August 2023 | E13: 2 | F13: =E13*400 -> 800 | G13: =COUNTIF(B:B,B13) -> 1 | H13: CHECKED (OK)
A14: 11 | B14: 1009011 | C14: =vlookup(B14,'Crew Data'!C:G,5,0) -> Weerayos Rungudomsinsakul | D14: 5-6 August 2023 | E14: 2 | F14: =E14*400 -> 800 | G14: =COUNTIF(B:B,B14) -> 1 | H14: CHECKED (OK)
A15: 12 | B15: 1019518 | C15: =vlookup(B15,'Crew Data'!C:G,5,0) -> Naratip Dumrongthai | D15: 8-9 August 2023 | E15: 2 | F15: =E15*400 -> 800 | G15: =COUNTIF(B:B,B15) -> 1 | H15: CHECKED (OK)
... A86: 83 | B86: 1001819 | C86: =vlookup(B86,'Crew Data'!C:G,5,0) -> #N/A | D86: 16-17 July 2023 | E86: 2 | F86: =E86*400 -> 800 | G86: =COUNTIF(B:B,B86) -> 1 | H86: CHECKED (OK)
A87: 84 | B87: 1004765 | C87: =vlookup(B87,'Crew Data'!C:G,5,0) -> Wasinee Leeopas | D87: 45169 | E87: 1 | F87: =E87*400 -> 400 | G87: =COUNTIF(B:B,B87) -> 1 | H87: CHECKED (OK)
A88: 85 | B88: 1017651 | C88: =vlookup(B88,'Crew Data'!C:G,5,0) -> Usana Saepua | D88: 30-31 August 2023 | E88: 2 | F88: =E88*400 -> 800 | G88: =COUNTIF(B:B,B88) -> 1 | H88: CHECKED (OK)
A89: 86 | B89: 1025302 | C89: =vlookup(B89,'Crew Data'!C:G,5,0) -> Krisana Sae-yang | D89: 30-31 August 2023 | E89: 2 | F89: =E89*400 -> 800 | G89: =COUNTIF(B:B,B89) -> 1 | H89: CHECKED (OK)
A90: 87 | B90: 1004030 | C90: =vlookup(B90,'Crew Data'!C:G,5,0) -> Kulpornpat Srikulchaipat | D90: 26-27 August 2023 | E90: 2 | F90: =E90*400 -> 800 | G90: =COUNTIF(B:B,B90) -> 1 | H90: CHECKED (OK)
A91: 88 | B91: 1013181 | C91: =vlookup(B91,'Crew Data'!C:G,5,0) -> Pattorn Kitthathamrong | D91: 21-22 May 2023 | E91: 2 | F91: =E91*400 -> 800 | G91: =COUNTIF(B:B,B91) -> 1 | H91: CHECKED (OK)

Sheet SEPTEMBER 23
A1: Perdiem Report in SEPTEMBER 2023 | H1: Last updated : 03 OCTOBER 2023 Time: 12.00 (Status : CLOSE)
A2: Item | B2: New ID No. | C2: Employee name | D2: Period | E2: Description
E3: Days | F3: Total Perdiem (THB) | H3: Cross Checked by Supervisor | I3: REMARK
A4: 1 | B4: 1004729 | C4: =vlookup(B4,'Crew Data'!C:G,5,0) -> Sasimon Chamnansarn | D4: 26-27 August 2023 | E4: 2 | F4: =E4*400 -> 800 | G4: =COUNTIF(B:B,B4) -> 1 | H4: CHECKED (OK)
A5: 2 | B5: 1003385 | C5: =vlookup(B5,'Crew Data'!C:G,5,0) -> Jaruma Jantarapap | D5: 3-4, 11-12, 17-18, 22-23, 25-26 August / 1-2, 6-7, 18-19 September 2023 | E5: 16 | F5: =E5*400 -> 6400 | G5: =COUNTIF(B:B,B5) -> 1 | H5: CHECKED (OK)
A6: 3 | B6: 1005297 | C6: =vlookup(B6,'Crew Data'!C:G,5,0) -> Kunapond Wutayatornsakul | D6: 2-3 September 2023 | E6: 2 | F6: =E6*400 -> 800 | G6: =COUNTIF(B:B,B6) -> 1 | H6: CHECKED (OK)
A7: 4 | B7: 1007011 | C7: =vlookup(B7,'Crew Data'!C:G,5,0) -> Jeeraprapa Tuptimdang | D7: 6-7 September 2023 | E7: 2 | F7: =E7*400 -> 800 | G7: =COUNTIF(B:B,B7) -> 1 | H7: CHECKED (OK)
A8: 5 | B8: 1014329 | C8: =vlookup(B8,'Crew Data'!C:G,5,0) -> Kanicha Sae-toen | D8: 5-6 September 2023 | E8: 2 | F8: =E8*400 -> 800 | G8: =COUNTIF(B:B,B8) -> 1 | H8: CHECKED (OK)
A9: 6 | B9: 1007276 | C9: =vlookup(B9,'Crew Data'!C:G,5,0) -> Teerayut Worawejwisarn | D9: 7-8 September 2023 | E9: 2 | F9: =E9*400 -> 800 | G9: =COUNTIF(B:B,B9) -> 1 | H9: CHECKED (OK)
A10: 7 | B10: 1012907 | C10: =vlookup(B10,'Crew Data'!C:G,5,0) -> Thiranuch Chantavarin | D10: 31 August / 01 September 2023 | E10: 2 | F10: =E10*400 -> 800 | G10: =COUNTIF(B:B,B10) -> 1 | H10: CHECKED (OK)
A11: 8 | B11: 1004765 | C11: =vlookup(B11,'Crew Data'!C:G,5,0) -> Wasinee Leeopas | D11: 31 August / 01 September 2023 | E11: 2 | F11: =E11*400 -> 800 | G11: =COUNTIF(B:B,B11) -> 1 | H11: CHECKED (OK)
A12: 9 | B12: 1006844 | C12: =vlookup(B12,'Crew Data'!C:G,5,0) -> Rada Nilyam | D12: 11-12 September 2023 | E12: 2 | F12: =E12*400 -> 800 | G12: =COUNTIF(B:B,B12) -> 1 | H12: CHECKED (OK)
A13: 10 | B13: 1003137 | C13: =vlookup(B13,'Crew Data'!C:G,5,0) -> Patcharamai Udomphol | D13: 4-5 September 2023 | E13: 2 | F13: =E13*400 -> 800 | G13: =COUNTIF(B:B,B13) -> 1 | H13: CHECKED (OK)
A14: 11 | B14: 1005906 | C14: =vlookup(B14,'Crew Data'!C:G,5,0) -> Supatra Pokkhabut | D14: 12-13 September 2023 | E14: 2 | F14: =E14*400 -> 800 | G14: =COUNTIF(B:B,B14) -> 1 | H14: CHECKED (OK)
A15: 12 | B15: 1009799 | C15: =vlookup(B15,'Crew Data'!C:G,5,0) -> Kittirat Aujsri | D15: 14-15 September 2023 | E15: 2 | F15: =E15*400 -> 800 | G15: =COUNTIF(B:B,B15) -> 1 | H15: CHECKED (OK)
... A88: 85 | B88: 1002984 | C88: =vlookup(B88,'Crew Data'!C:G,5,0) -> Praepailin Luckanatin | D88: 30-31 August 2023 | E88: 2 | F88: =E88*400 -> 800 | G88: =COUNTIF(B:B,B88) -> 1 | H88: CHECKED (OK)

Sheet OCTOBER 23
A1: Perdiem Report in OCTOBER 2023 | H1: Last updated : 01 NOVEMBER 2023 Time: 12.00 (Status : CLOSE)
A2: Item | B2: New ID No. | C2: Employee name | D2: Period | E2: Description
E3: Days | F3: Total Perdiem (THB) | H3: Cross Checked by Supervisor | I3: REMARK
A4: 1 | B4: 1007009 | C4: =vlookup(B4,'Crew Data'!C:G,5,0) -> Busayarat Pongratanakul | D4: 30 September / 1, 12-13 October 2023 | E4: 4 | F4: =E4*400 -> 1600 | G4: =COUNTIF(B:B,B4) -> 1 | H4: CHECKED (OK)
A5: 2 | B5: 1007029 | C5: =vlookup(B5,'Crew Data'!C:G,5,0) -> Pitchaya Dalai | D5: 16-17 September 2023 | E5: 2 | F5: =E5*400 -> 800 | G5: =COUNTIF(B:B,B5) -> 1 | H5: CHECKED (OK)
A6: 3 | B6: 1005303 | C6: =vlookup(B6,'Crew Data'!C:G,5,0) -> Piyathida Jaikla | D6: 27-28 September 2023 | E6: 2 | F6: =E6*400 -> 800 | G6: =COUNTIF(B:B,B6) -> 1 | H6: CHECKED (OK)
A7: 4 | B7: 1005828 | C7: =vlookup(B7,'Crew Data'!C:G,5,0) -> Piyawan Panitanthum | D7: 30 September / 1 October 2023 | E7: 2 | F7: =E7*400 -> 800 | G7: =COUNTIF(B:B,B7) -> 1 | H7: CHECKED (OK)
A8: 5 | B8: 1014665 | C8: =vlookup(B8,'Crew Data'!C:G,5,0) -> Jaruwan Charoenratanapirom | D8: 3-4 October 2023 | E8: 2 | F8: =E8*400 -> 800 | G8: =COUNTIF(B:B,B8) -> 1 | H8: CHECKED (OK)
A9: 6 | B9: 1011848 | C9: =vlookup(B9,'Crew Data'!C:G,5,0) -> Wiput Janvanichstaporn | D9: 3-4 October 2023 | E9: 2 | F9: =E9*400 -> 800 | G9: =COUNTIF(B:B,B9) -> 1 | H9: CHECKED (OK)
A10: 7 | B10: 1011504 | C10: =vlookup(B10,'Crew Data'!C:G,5,0) -> Punyanuch Skulnukulkit | D10: 1-2 October 2023 | E10: 2 | F10: =E10*400 -> 800 | G10: =COUNTIF(B:B,B10) -> 1 | H10: CHECKED (OK)
A11: 8 | B11: 1023594 | C11: =vlookup(B11,'Crew Data'!C:G,5,0) -> Teerada Sripochsomboon | D11: 5-6 October 2023 | E11: 2 | F11: =E11*400 -> 800 | G11: =COUNTIF(B:B,B11) -> 1 | H11: CHECKED (OK)
A12: 9 | B12: 1023582 | C12: =vlookup(B12,'Crew Data'!C:G,5,0) -> Rawiwan Chailerst | D12: 5-6 October 2023 | E12: 2 | F12: =E12*400 -> 800 | G12: =COUNTIF(B:B,B12) -> 1 | H12: CHECKED (OK)
A13: 10 | B13: 1023581 | C13: =vlookup(B13,'Crew Data'!C:G,5,0) -> Pavitra Chaosrithong | D13: 10-11 September / 5-6 October 2023 | E13: 4 | F13: =E13*400 -> 1600 | G13: =COUNTIF(B:B,B13) -> 1 | H13: CHECKED (OK)
A14: 11 | B14: 1008956 | C14: =vlookup(B14,'Crew Data'!C:G,5,0) -> Duangkamon Thongfuang | D14: 2-3 October 2023 | E14: 2 | F14: =E14*400 -> 800 | G14: =COUNTIF(B:B,B14) -> 1 | H14: CHECKED (OK)
A15: 12 | B15: 1019407 | C15: =vlookup(B15,'Crew Data'!C:G,5,0) -> Saowapak Siri-athikhom | D15: 7-8 October 2023 | E15: 2 | F15: =E15*400 -> 800 | G15: =COUNTIF(B:B,B15) -> 1 | H15: CHECKED (OK)
... A72: 69 | B72: 1002984 | C72: =vlookup(B72,'Crew Data'!C:G,5,0) -> Praepailin Luckanatin | D72: 10-11, 22-23 October 2023 | E72: 4 | F72: =E72*400 -> 1600 | G72: =COUNTIF(B:B,B72) -> 1 | H72: CHECKED (OK)

Sheet NOVEMBER 23
A1: Perdiem Report in NOVEMBER 2023 | H1: Last updated : 2 DECEMBER 2023 Time: 12.00 (Status : CLOSE)
A2: Item | B2: New ID No. | C2: Employee name | D2: Period | E2: Description
E3: Days | F3: Total Perdiem (THB) | H3: Cross Checked by Supervisor | I3: REMARK
A4: 1 | B4: 1005964 | C4: =vlookup(B4,'Crew Data'!C:G,5,0) -> Sawitri Siribunrueangwong | D4: 10-11 October 2023 | E4: 2 | F4: =E4*400 -> 800 | G4: =COUNTIF(B:B,B4) -> 1 | H4: CHECKED (OK)
A5: 2 | B5: 1025323 | C5: =vlookup(B5,'Crew Data'!C:G,5,0) -> Jariya Tangmahamek | D5: 8-9 September 2023 | E5: 2 | F5: =E5*400 -> 800 | G5: =COUNTIF(B:B,B5) -> 1 | H5: CHECKED (OK)
A6: 3 | B6: 1006835 | C6: =vlookup(B6,'Crew Data'!C:G,5,0) -> Ketsaraporn Borvornmongkolsak | D6: 9-10, 17-18 October 2023 | E6: 4 | F6: =E6*400 -> 1600 | G6: =COUNTIF(B:B,B6) -> 1 | H6: CHECKED (OK)
A7: 4 | B7: 1014064 | C7: =vlookup(B7,'Crew Data'!C:G,5,0) -> Jaraspak Plengkhum | D7: 25-26 October 2023 | E7: 2 | F7: =E7*400 -> 800 | G7: =COUNTIF(B:B,B7) -> 1 | H7: CHECKED (OK)
A8: 5 | B8: 1014678 | C8: =vlookup(B8,'Crew Data'!C:G,5,0) -> Supapong Kwanon | D8: 14-15 October 2023 | E8: 2 | F8: =E8*400 -> 800 | G8: =COUNTIF(B:B,B8) -> 1 | H8: CHECKED (OK)
A9: 6 | B9: 1019555 | C9: =vlookup(B9,'Crew Data'!C:G,5,0) -> #N/A | D9: 4-5 October 2023 | E9: 2 | F9: =E9*400 -> 800 | G9: =COUNTIF(B:B,B9) -> 1 | H9: CHECKED (OK)
A10: 7 | B10: 1005759 | C10: =vlookup(B10,'Crew Data'!C:G,5,0) -> Nirinya Arunthanakulphat | D10: 2-3 October 2023 | E10: 2 | F10: =E10*400 -> 800 | G10: =COUNTIF(B:B,B10) -> 1 | H10: CHECKED (OK)

Sheet DECEMBER 2023
A1: Perdiem Report in DECEMBER 2023 | H1: Last updated : 03 January 2024 Time: 12.00 (Status : CLOSE)
A2: Item | B2: New ID No. | C2: Employee name | D2: Period | E2: Description
E3: Days | F3: Total Perdiem (THB) | H3: Cross Checked by Supervisor | I3: REMARK
C4: =vlookup(B4,'Crew Data'!C:G,5,0) -> #N/A | F4: =E4*400 -> 0 | G4: =COUNTIF(B:B,B4) -> 0
A7: ไม่มีการทำจ่ายเงินค่า Posting

Sheet MAY 2024
A1: Perdiem Report in MAY 2024 | H1: Last updated : 04 JUN 2024 Time: 12.00 (Status : CLOSE)
A2: Item | B2: New ID No. | C2: Employee name | D2: Period | E2: Description
E3: Days | F3: Total Perdiem (THB) | H3: Cross Checked by Supervisor | I3: REMARK
C4: =vlookup(B4,'Crew Data'!C:G,5,0) -> #N/A | F4: =E4*400 -> 0 | G4: =COUNTIF(B:B,B4) -> 0
A7: ไม่มีการทำจ่ายเงินค่า Posting

Sheet JUNE 2024
A1: Perdiem Report in JUNE 2024 | H1: Last updated : 01 JUL 2024 Time: 12.00 (Status : CLOSE)
A2: Item | B2: New ID No. | C2: Employee name | D2: Period | E2: Description
E3: Days | F3: Total Perdiem (THB) | H3: Cross Checked by Supervisor | I3: REMARK
C4: =vlookup(B4,'Crew Data'!C:G,5,0) -> #N/A | F4: =E4*400 -> 0 | G4: =COUNTIF(B:B,B4) -> 0
A7: ไม่มีการทำจ่ายเงินค่า Posting

Sheet JULY 2024
A1: Perdiem Report in JULY 2024 | H1: Last updated : 01 AUG 2024 Time: 12.00 (Status : CLOSE)
A2: Item | B2: New ID No. | C2: Employee name | D2: Period | E2: Description
E3: Days | F3: Total Perdiem (THB) | H3: Cross Checked by Supervisor | I3: REMARK
C4: =vlookup(B4,'Crew Data'!C:G,5,0) -> #N/A | F4: =E4*400 -> 0 | G4: =COUNTIF(B:B,B4) -> 0
A7: ไม่มีการทำจ่ายเงินค่า Posting

Sheet AUGUST 2024
A1: Perdiem Report in AUGUST 2024 | H1: Last updated : 01 SEP 2024 Time: 12.00 (Status : CLOSE)
A2: Item | B2: New ID No. | C2: Employee name | D2: Period | E2: Description
E3: Days | F3: Total Perdiem (THB) | H3: Cross Checked by Supervisor | I3: REMARK
C4: =vlookup(B4,'Crew Data'!C:G,5,0) -> #N/A | F4: =E4*400 -> 0 | G4: =COUNTIF(B:B,B4) -> 0
A7: ไม่มีการทำจ่ายเงินค่า Posting

Sheet SEPTEMBER 2024
A1: Perdiem Report in SEPTEMBER 2024 | H1: Last updated : 02 OCT 2024 Time: 12.00 (Status : CLOSE)
A2: Item | B2: New ID No. | C2: Employee name | D2: Period | E2: Description
E3: Days | F3: Total Perdiem (THB) | H3: Cross Checked by Supervisor | I3: REMARK
C4: =vlookup(B4,'Crew Data'!C:G,5,0) -> #N/A | F4: =E4*400 -> 0 | G4: =COUNTIF(B:B,B4) -> 0
A7: ไม่มีการทำจ่ายเงินค่า Posting

Sheet October 2024
A1: Perdiem Report in OCTOBER 2024 | H1: Last updated : 01 NOV 2024 Time: 12.00 (Status : CLOSE)
A2: Item | B2: New ID No. | C2: Employee name | D2: Period | E2: Description
E3: Days | F3: Total Perdiem (THB) | H3: Cross Checked by Supervisor | I3: REMARK
A4: 1 | B4: 1004016 | C4: =vlookup(B4,'Crew Data'!C:G,5,0) -> Khamkhun Thapnoo | D4: 45596 | E4: 1 | F4: =E4*400 -> 400 | G4: =COUNTIF(B:B,B4) -> 1
A5: 2 | B5: 1004683 | C5: =vlookup(B5,'Crew Data'!C:G,5,0) -> Prok Lartham | D5: 28 OCTOBER 2024 - 31 OCTOBER 2024 | E5: 4 | F5: =E5*400 -> 1600 | G5: =COUNTIF(B:B,B5) -> 1
A6: 3 | B6: 1013178 | C6: =vlookup(B6,'Crew Data'!C:G,5,0) -> Niharoon Sulaiman | D6: 28 OCTOBER 2024 - 31 OCTOBER 2024 | E6: 4 | F6: =E6*400 -> 1600 | G6: =COUNTIF(B:B,B6) -> 1
A7: 4 | B7: 1007007 | C7: =vlookup(B7,'Crew Data'!C:G,5,0) -> Aram Nukulpakdee | D7: 45596 | E7: 1 | F7: =E7*400 -> 400 | G7: =COUNTIF(B:B,B7) -> 1
A8: 5 | B8: 1011513 | C8: =vlookup(B8,'Crew Data'!C:G,5,0) -> Rawitnat Marayat | D8: 29 OCTOBER 2024 - 30 OCTOBER 2024 | E8: 2 | F8: =E8*400 -> 800 | G8: =COUNTIF(B:B,B8) -> 1
A9: 6 | B9: 1003365 | C9: =vlookup(B9,'Crew Data'!C:G,5,0) -> Napatchol Wongwuttito | D9: 28 OCTOBER 2024 - 31 OCTOBER 2024 | E9: 4 | F9: =E9*400 -> 1600 | G9: =COUNTIF(B:B,B9) -> 1
A10: 7 | B10: 1010731 | C10: =vlookup(B10,'Crew Data'!C:G,5,0) -> Samatikan Boonket | D10: 45596 | E10: 1 | F10: =E10*400 -> 400 | G10: =COUNTIF(B:B,B10) -> 1
A11: 8 | B11: 1007032 | C11: =vlookup(B11,'Crew Data'!C:G,5,0) -> Praew Kijsuwan | D11: 45597 | E11: 1 | F11: =E11*400 -> 400 | G11: =COUNTIF(B:B,B11) -> 1
A12: 9 | B12: 1022215 | C12: =vlookup(B12,'Crew Data'!C:G,5,0) -> Porntida Yuttimi | D12: 45598 | E12: 1 | F12: =E12*400 -> 400 | G12: =COUNTIF(B:B,B12) -> 1

Sheet NOVEMBER 2024
A1: Perdiem Report in NOVEMBER 2024 | H1: Last updated : 02 NOV 2024 Time: 12.00 (Status : OPEN)
A2: Item | B2: New ID No. | C2: Employee name | D2: Period | E2: Description
E3: Days | F3: Total Perdiem (THB) | H3: Cross Checked by Supervisor | I3: REMARK
A4: 1 | B4: 1015093 | C4: =vlookup(B4,'Crew Data'!C:G,5,0) -> Sampan Simpalipan | D4: 29 October 2024 - 31 October 2024 1 November 2024 - 30 November 2024 | E4: 33 | F4: =E4*400 -> 13200 | G4: =COUNTIF(B:B,B4) -> 1 | H4: CHECKED (OK)
A5: 2 | B5: 1004197 | C5: =vlookup(B5,'Crew Data'!C:G,5,0) -> Kultharin Kijbamrunglab | D5: 2 November 2024 - 3 November 2024 | E5: 2 | F5: =E5*400 -> 800 | G5: =COUNTIF(B:B,B5) -> 1 | H5: CHECKED (OK)
A6: 3 | B6: 1040522 | C6: =vlookup(B6,'Crew Data'!C:G,5,0) -> Titapa Tiyasoponjit | D6: 5 November 2024 - 6 November 2024 | E6: 2 | F6: =E6*400 -> 800 | G6: =COUNTIF(B:B,B6) -> 1 | H6: CHECKED (OK)
A7: 4 | B7: 1017975 | C7: =vlookup(B7,'Crew Data'!C:G,5,0) -> Nilin Ngampuak | D7: 5 November 2024 - 6 November 2024 | E7: 2 | F7: =E7*400 -> 800 | G7: =COUNTIF(B:B,B7) -> 1 | H7: CHECKED (OK)
A8: 5 | B8: 1014554 | C8: =vlookup(B8,'Crew Data'!C:G,5,0) -> Katthareeya Trachoowanich | D8: 2 November 2024 - 3 November 2024 | E8: 2 | F8: =E8*400 -> 800 | G8: =COUNTIF(B:B,B8) -> 1 | H8: CHECKED (OK)
A9: 6 | B9: 1007014 | C9: =vlookup(B9,'Crew Data'!C:G,5,0) -> Piyanut Nainet | D9: 9 November 2024 - 10 November 2024 | E9: 2 | F9: =E9*400 -> 800 | G9: =COUNTIF(B:B,B9) -> 1 | H9: CHECKED (OK)
A10: 7 | B10: 1022215 | C10: =vlookup(B10,'Crew Data'!C:G,5,0) -> Porntida Yuttimi | D10: 1 November 2024 | E10: 1 | F10: =E10*400 -> 400 | G10: =COUNTIF(B:B,B10) -> 1 | H10: CHECKED (OK)
A11: 8 | B11: 1004531 | C11: =vlookup(B11,'Crew Data'!C:G,5,0) -> Nattakan Kanokpantarakorn | D11: 9 November 2024 - 10 November 2024 | E11: 2 | F11: =E11*400 -> 800 | G11: =COUNTIF(B:B,B11) -> 1 | H11: CHECKED (OK)
A12: 9 | B12: 1015096 | C12: =vlookup(B12,'Crew Data'!C:G,5,0) -> Thiranart Ponglongkhum | D12: 5 November 2024 - 6 November 2024 | E12: 2 | F12: =E12*400 -> 800 | G12: =COUNTIF(B:B,B12) -> 1 | H12: CHECKED (OK)
A13: 10 | B13: 1003392 | C13: =vlookup(B13,'Crew Data'!C:G,5,0) -> Punnaphas Tawornpanmanee | D13: 16 November 2024 - 17 November 2024 | E13: 2 | F13: =E13*400 -> 800 | G13: =COUNTIF(B:B,B13) -> 1 | H13: CHECKED (OK)
A14: 11 | B14: 1013576 | C14: =vlookup(B14,'Crew Data'!C:G,5,0) -> Pawarisar Samanthong | D14: 21 November 2024 - 22 November 2024 | E14: 2 | F14: =E14*400 -> 800 | G14: =COUNTIF(B:B,B14) -> 1 | H14: CHECKED (OK)
A15: 12 | B15: 1007157 | C15: =vlookup(B15,'Crew Data'!C:G,5,0) -> Pichanun Seneetantikul | D15: 19 November 2024 - 20 November 2024 | E15: 2 | F15: =E15*400 -> 800 | G15: =COUNTIF(B:B,B15) -> 1 | H15: CHECKED (OK)
... A35: 33 | B35: 1004213 | C35: =vlookup(B35,'Crew Data'!C:G,5,0) -> Worapada Suetrongmunkong | D35: 2 November 2024 - 3 November 2024 | E35: 2 | F35: =E35*400 -> 800 | G35: =COUNTIF(B:B,B35) -> 1 | H35: CHECKED (OK)

Sheet DECEMBER 2024
A1: Perdiem Report in DECEMBER 2024 | H1: Last updated : 02 JAN 2024 Time: 12.00 (Status : CLOSE)
A2: Item | B2: New ID No. | C2: Employee name | D2: Period | E2: Description
E3: Days | F3: Total Perdiem (THB) | H3: Cross Checked by Supervisor | I3: REMARK
A4: 1 | B4: 1019193 | C4: =vlookup(B4,'Crew Data'!C:G,5,0) -> Nattaporn Pattarasiriwong | D4: 26 November 2024 - 27 November 2024 / 10 December 2024 - 11 December 2024 | E4: 4 | F4: =E4*400 -> 1600 | G4: =COUNTIF(B:B,B4) -> 1 | H4: CHECKED (OK)
A5: 2 | B5: 1001822 | C5: =vlookup(B5,'Crew Data'!C:G,5,0) -> Wilasinee Natenopparat | D5: 12 November 2024 - 13 November 2024 | E5: 2 | F5: =E5*400 -> 800 | G5: =COUNTIF(B:B,B5) -> 1 | H5: CHECKED (OK)
A6: 3 | B6: 1040338 | C6: =vlookup(B6,'Crew Data'!C:G,5,0) -> Piyakorn Sripraphan | D6: 21 November 2024 - 22 November 2024 | E6: 2 | F6: =E6*400 -> 800 | G6: =COUNTIF(B:B,B6) -> 1 | H6: CHECKED (OK)
A7: 4 | B7: 1004298 | C7: =vlookup(B7,'Crew Data'!C:G,5,0) -> Teerapat Kasemphongsakorn | D7: 3 November 2024 - 4 November 2024 | E7: 2 | F7: =E7*400 -> 800 | G7: =COUNTIF(B:B,B7) -> 1 | H7: CHECKED (OK)
A8: 5 | B8: 1015412 | C8: =vlookup(B8,'Crew Data'!C:G,5,0) -> Sitthiphath Ratanaborvornsethi | D8: 3 December 2024 - 4 December 2024 | E8: 2 | F8: =E8*400 -> 800 | G8: =COUNTIF(B:B,B8) -> 1 | H8: CHECKED (OK)
A9: 6 | B9: 1025144 | C9: =vlookup(B9,'Crew Data'!C:G,5,0) -> Maythawee Krabuansri | D9: 10 December 2024 - 11 December 2024 | E9: 2 | F9: =E9*400 -> 800 | G9: =COUNTIF(B:B,B9) -> 1 | H9: CHECKED (OK)
A10: 7 | B10: 1004541 | C10: =vlookup(B10,'Crew Data'!C:G,5,0) -> Varaporn Rattanamahasalchai | D10: 21 December 2024 - 22 December 2024 | E10: 2 | F10: =E10*400 -> 800 | G10: =COUNTIF(B:B,B10) -> 1 | H10: CHECKED (OK)
A11: 8 | B11: 1004047 | C11: =vlookup(B11,'Crew Data'!C:G,5,0) -> Sunisa Panhirun | D11: 21 December 2024 - 22 December 2024 | E11: 2 | F11: =E11*400 -> 800 | G11: =COUNTIF(B:B,B11) -> 1 | H11: CHECKED (OK)
A12: 9 | B12: 1016385 | C12: =vlookup(B12,'Crew Data'!C:G,5,0) -> Raweewan Sritong | D12: 7 December 2024 - 8 December 2024 | E12: 2 | F12: =E12*400 -> 800 | G12: =COUNTIF(B:B,B12) -> 1 | H12: CHECKED (OK)
A13: 10 | B13: 1011844 | C13: =vlookup(B13,'Crew Data'!C:G,5,0) -> Thanyaporn Vaivattana | D13: 24 December 2024 - 25 December 2024 | E13: 2 | F13: =E13*400 -> 800 | G13: =COUNTIF(B:B,B13) -> 1 | H13: CHECKED (OK)
A14: 11 | B14: 1013033 | C14: =vlookup(B14,'Crew Data'!C:G,5,0) -> Sirirat Thampipat | D14: 17 December 2024 - 18 December 2024 | E14: 2 | F14: =E14*400 -> 800 | G14: =COUNTIF(B:B,B14) -> 1 | H14: CHECKED (OK)
A15: 12 | B15: 1011513 | C15: =vlookup(B15,'Crew Data'!C:G,5,0) -> Rawitnat Marayat | D15: 45627 | E15: 1 | F15: =E15*400 -> 400 | G15: =COUNTIF(B:B,B15) -> 1 | H15: CHECKED (OK)
A16: 13 | B16: 1015096 | C16: =vlookup(B16,'Crew Data'!C:G,5,0) -> Thiranart Ponglongkhum | D16: 5 December 2024 - 6 December 2024 | E16: 2 | F16: =E16*400 -> 800 | G16: =COUNTIF(B:B,B16) -> 1 | H16: CHECKED (OK)
A17: 14 | B17: 1014554 | C17: =vlookup(B17,'Crew Data'!C:G,5,0) -> Katthareeya Trachoowanich | D17: 12 December 2024 - 13 December 2024 | E17: 2 | F17: =E17*400 -> 800 | G17: =COUNTIF(B:B,B17) -> 1 | H17: CHECKED (OK)
A18: 15 | B18: 1007032 | C18: =vlookup(B18,'Crew Data'!C:G,5,0) -> Praew Kijsuwan | D18: 10 December 2024 - 11 December 2024 | E18: 2 | F18: =E18*400 -> 800 | G18: =COUNTIF(B:B,B18) -> 1 | H18: CHECKED (OK)
A19: 16 | B19: 1007026 | C19: =vlookup(B19,'Crew Data'!C:G,5,0) -> Kwanrapee Satayayookt | D19: 10 December 2024 - 11 December 2024 | E19: 2 | F19: =E19*400 -> 800 | G19: =COUNTIF(B:B,B19) -> 1 | H19: CHECKED (OK)
A20: 17 | B20: 1004127 | C20: =vlookup(B20,'Crew Data'!C:G,5,0) -> Thawinun Arunnuntapanich | D20: 45657 | E20: 1 | F20: =E20*400 -> 400 | G20: =COUNTIF(B:B,B20) -> 1 | H20: CHECKED (OK)
A21: 18 | B21: 1019551 | C21: =vlookup(B21,'Crew Data'!C:G,5,0) -> Thanyatorn Panyanonwat | D21: 45657 | E21: 1 | F21: =E21*400 -> 400 | G21: =COUNTIF(B:B,B21) -> 1 | H21: CHECKED (OK)
A22: 19 | B22: 1014262 | C22: =vlookup(B22,'Crew Data'!C:G,5,0) -> Wongsakorn Chumniwatesa | D22: 45657 | E22: 1 | F22: =E22*400 -> 400 | G22: =COUNTIF(B:B,B22) -> 1 | H22: CHECKED (OK)
A23: 20 | B23: 1010916 | C23: =vlookup(B23,'Crew Data'!C:G,5,0) -> Sivakorn Sangsukiam | D23: 12 December 2024 - 13 December 2024 | E23: 2 | F23: =E23*400 -> 800 | G23: =COUNTIF(B:B,B23) -> 1 | H23: CHECKED (OK)
A24: 21 | B24: 1005301 | C24: =vlookup(B24,'Crew Data'!C:G,5,0) -> Pimpaporn Sittitanggoon | D24: 26 November 2024 - 27 November 2024 | E24: 2 | F24: =E24*400 -> 800 | G24: =COUNTIF(B:B,B24) -> 1 | H24: CHECKED (OK)
A25: 22 | B25: 1001082 | C25: =vlookup(B25,'Crew Data'!C:G,5,0) -> Pobsaran Chantaratim | D25: 17 December 2024 - 18 December 2024 | E25: 2 | F25: =E25*400 -> 800 | G25: =COUNTIF(B:B,B25) -> 1 | H25: CHECKED (OK)
A26: 23 | B26: 1003392 | C26: =vlookup(B26,'Crew Data'!C:G,5,0) -> Punnaphas Tawornpanmanee | D26: 21 December 2024 - 22 December 2024 | E26: 2 | F26: =E26*400 -> 800 | G26: =COUNTIF(B:B,B26) -> 1 | H26: CHECKED (OK)
A27: 24 | B27: 1012554 | C27: =vlookup(B27,'Crew Data'!C:G,5,0) -> Bhuriwat Udomphol | D27: 14 December 2024 - 15 December 2024 21 December 2024 - 22 December 2024 | E27: 4 | F27: =E27*400 -> 1600 | G27: =COUNTIF(B:B,B27) -> 1 | H27: CHECKED (OK)
A28: 25 | B28: 1004016 | C28: =vlookup(B28,'Crew Data'!C:G,5,0) -> Khamkhun Thapnoo | D28: 1 December 2024 - 15 December 2024 17 December 2024 - 29 December 2024 31 December 2024 | E28: 29 | F28: =E28*400 -> 11600 | G28: =COUNTIF(B:B,B28) -> 1 | H28: CHECKED (OK)
A29: 26 | B29: 1005972 | C29: =vlookup(B29,'Crew Data'!C:G,5,0) -> Wuttipon Onpuns | D29: 1 December 2024 - 31 December 2024 | E29: 31 | F29: =E29*400 -> 12400 | G29: =COUNTIF(B:B,B29) -> 1 | H29: CHECKED (OK)
A30: 27 | B30: 1025306 | C30: =vlookup(B30,'Crew Data'!C:G,5,0) -> Soravis Kissanaviparkporn | D30: 6 December 2024 - 31 December 2024 | E30: 26 | F30: =E30*400 -> 10400 | G30: =COUNTIF(B:B,B30) -> 1 | H30: CHECKED (OK)
A31: 28 | B31: 1005762 | C31: =vlookup(B31,'Crew Data'!C:G,5,0) -> Photchara Srisuk | D31: 1 December 2024 - 31 December 2024 | E31: 31 | F31: =E31*400 -> 12400 | G31: =COUNTIF(B:B,B31) -> 1 | H31: CHECKED (OK)
A32: 29 | B32: 1009768 | C32: =vlookup(B32,'Crew Data'!C:G,5,0) -> Thidech Eakmongkollert | D32: 1 December 2024 - 8 December 2024 10 December 2024 - 31 December 2024 | E32: 30 | F32: =E32*400 -> 12000 | G32: =COUNTIF(B:B,B32) -> 1 | H32: CHECKED (OK)
A33: 30 | B33: 1009757 | C33: =vlookup(B33,'Crew Data'!C:G,5,0) -> Pattrawan Wongchirawat | D33: 1 December 2024 5 December 2024 - 31 December 2024 | E33: 28 | F33: =E33*400 -> 11200 | G33: =COUNTIF(B:B,B33) -> 1 | H33: CHECKED (OK)
A34: 31 | B34: 1011510 | C34: =vlookup(B34,'Crew Data'!C:G,5,0) -> Nitinai Chalongtrakul | D34: 28 December 2024 - 29 December 2024 | E34: 2 | F34: =E34*400 -> 800 | G34: =COUNTIF(B:B,B34) -> 1 | H34: CHECKED (OK)
... A36: 33 | B36: 1009434 | C36: =vlookup(B36,'Crew Data'!C:G,5,0) -> Wanpiya Kaewyok | D36: 12 December 2024 - 13 December 2024 | E36: 2 | F36: =E36*400 -> 800 | G36: =COUNTIF(B:B,B36) -> 1 | H36: CHECKED (OK)

Sheet JANUARY 2025
A1: Perdiem Report in JANUARY 2025 | H1: Last updated : 03 FEB 2025 Time: 12.00 (Status : OPEN)
A2: Item | B2: New ID No. | C2: Employee name | D2: Period | E2: Description
E3: Days | F3: Total Perdiem (THB) | H3: Cross Checked by Supervisor | I3: REMARK
A4: 1 | B4: 1022213 | C4: =vlookup(B4,'Crew Data'!C:G,5,0) -> Puripak Pensawat | D4: 2 January 2025 - 3 January 2025 | E4: 2 | F4: =E4*400 -> 800 | G4: =COUNTIF(B:B,B4) -> 1 | H4: CHECKED (OK)
A5: 2 | B5: 1011800 | C5: =vlookup(B5,'Crew Data'!C:G,5,0) -> Arisa Witthawaskul | D5: 4 January 2025 - 5 January 2025 | E5: 2 | F5: =E5*400 -> 800 | G5: =COUNTIF(B:B,B5) -> 1 | H5: CHECKED (OK)
A6: 3 | B6: 1012362 | C6: =vlookup(B6,'Crew Data'!C:G,5,0) -> Patcharagorn Chankhong | D6: 4 January 2025 - 5 January 2025 | E6: 2 | F6: =E6*400 -> 800 | G6: =COUNTIF(B:B,B6) -> 1 | H6: CHECKED (OK)
A7: 4 | B7: 1006995 | C7: =vlookup(B7,'Crew Data'!C:G,5,0) -> Kornrumpha Wongsing | D7: 2 January 2025 - 3 January 2025 | E7: 2 | F7: =E7*400 -> 800 | G7: =COUNTIF(B:B,B7) -> 1 | H7: CHECKED (OK)
A8: 5 | B8: 1006991 | C8: =vlookup(B8,'Crew Data'!C:G,5,0) -> Chattamanuch Thiamhong | D8: 45658 | E8: 1 | F8: =E8*400 -> 400 | G8: =COUNTIF(B:B,B8) -> 1 | H8: CHECKED (OK)
A9: 6 | B9: 1009757 | C9: =vlookup(B9,'Crew Data'!C:G,5,0) -> Pattrawan Wongchirawat | D9: 45658 | E9: 1 | F9: =E9*400 -> 400 | G9: =COUNTIF(B:B,B9) -> 1 | H9: CHECKED (OK)
A10: 7 | B10: 1025186 | C10: =vlookup(B10,'Crew Data'!C:G,5,0) -> Pawaran Modsuwan | D10: 7 January 2025 - 8 January 2025 | E10: 2 | F10: =E10*400 -> 800 | G10: =COUNTIF(B:B,B10) -> 1 | H10: CHECKED (OK)
A11: 8 | B11: 1006870 | C11: =vlookup(B11,'Crew Data'!C:G,5,0) -> Duangporn Denkesineelam | D11: 9 January 2025 - 10 January 2025 | E11: 2 | F11: =E11*400 -> 800 | G11: =COUNTIF(B:B,B11) -> 1 | H11: CHECKED (OK)
A12: 9 | B12: 1004531 | C12: =vlookup(B12,'Crew Data'!C:G,5,0) -> Nattakan Kanokpantarakorn | D12: 11 January 2025 - 12 January 2025 | E12: 2 | F12: =E12*400 -> 800 | G12: =COUNTIF(B:B,B12) -> 1 | H12: CHECKED (OK)
A13: 10 | B13: 1040505 | C13: =vlookup(B13,'Crew Data'!C:G,5,0) -> Atchamaporn Pimrin | D13: 11 January 2025 - 12 January 2025 | E13: 2 | F13: =E13*400 -> 800 | G13: =COUNTIF(B:B,B13) -> 1 | H13: CHECKED (OK)
A14: 11 | B14: 1040868 | C14: =vlookup(B14,'Crew Data'!C:G,5,0) -> Napatchakorn Khaminbut | D14: 14 January 2025 - 15 January 2025 | E14: 2 | F14: =E14*400 -> 800 | G14: =COUNTIF(B:B,B14) -> 1 | H14: CHECKED (OK)
A15: 12 | B15: 1019518 | C15: =vlookup(B15,'Crew Data'!C:G,5,0) -> Naratip Dumrongthai | D15: 16 January 2025 - 17 January 2025 | E15: 2 | F15: =E15*400 -> 800 | G15: =COUNTIF(B:B,B15) -> 1 | H15: CHECKED (OK)
A16: 13 | B16: 1015405 | C16: =vlookup(B16,'Crew Data'!C:G,5,0) -> Nuttapon Pungjun | D16: 16 January 2025 - 17 January 2025 | E16: 2 | F16: =E16*400 -> 800 | G16: =COUNTIF(B:B,B16) -> 1 | H16: CHECKED (OK)
A17: 14 | B17: 1001822 | C17: =vlookup(B17,'Crew Data'!C:G,5,0) -> Wilasinee Natenopparat | D17: 7 January 2025 - 8 January 2025 | E17: 2 | F17: =E17*400 -> 800 | G17: =COUNTIF(B:B,B17) -> 1 | H17: CHECKED (OK)
A18: 15 | B18: 1012158 | C18: =vlookup(B18,'Crew Data'!C:G,5,0) -> Itthipong Khanthonglor | D18: 21 January 2025 - 22 January 2025 | E18: 2 | F18: =E18*400 -> 800 | G18: =COUNTIF(B:B,B18) -> 1 | H18: CHECKED (OK)
A19: 16 | B19: 1000486 | C19: =vlookup(B19,'Crew Data'!C:G,5,0) -> Ratthinan Wasupornwiboon | D19: 14 January 2025 - 15 January 2025 | E19: 2 | F19: =E19*400 -> 800 | G19: =COUNTIF(B:B,B19) -> 1 | H19: CHECKED (OK)
A20: 17 | B20: 1011516 | C20: =vlookup(B20,'Crew Data'!C:G,5,0) -> Thitipol Soontorn-Anantakul | D20: 7 January 2025 - 8 January 2025 | E20: 2 | F20: =E20*400 -> 800 | G20: =COUNTIF(B:B,B20) -> 1 | H20: CHECKED (OK)
A21: 18 | B21: 1011762 | C21: =vlookup(B21,'Crew Data'!C:G,5,0) -> Tritotsaporn Ketudat | D21: 18 January 2025 - 19 January 2025 | E21: 2 | F21: =E21*400 -> 800 | G21: =COUNTIF(B:B,B21) -> 1 | H21: CHECKED (OK)
... A53: 50 | B53: 1000736 | C53: =vlookup(B53,'Crew Data'!C:G,5,0) -> Ekkachai Moolla | D53: 19 December 2024 - 20 December 2024 | E53: 2 | F53: =E53*400 -> 800 | G53: =COUNTIF(B:B,B53) -> 1 | H53: CHECKED (OK)

Sheet FEBUARY 2025
A1: Perdiem Report in FEBUARY 2025 | H1: Last updated : 3 MAR 2025 Time: 12.00 (Status : CLOSED)
A2: Item | B2: New ID No. | C2: Employee name | D2: Period | E2: Description
E3: Days | F3: Total Perdiem (THB) | H3: Cross Checked by Supervisor | I3: REMARK
A4: 1 | B4: 1012680 | C4: =vlookup(B4,'Crew Data'!C:G,5,0) -> Wiracha Chamsoongnern | D4: 14 January 2025 - 15 January 2025 | E4: 2 | F4: =E4*400 -> 800 | G4: =COUNTIF(B:B,B4) -> 1 | H4: CHECKED (OK) | I4: ตกเบิกเดือนมกราคม 68
A5: 2 | B5: 1004127 | C5: =vlookup(B5,'Crew Data'!C:G,5,0) -> Thawinun Arunnuntapanich | D5: 45658 | E5: 1 | F5: =E5*400 -> 400 | G5: =COUNTIF(B:B,B5) -> 1 | H5: CHECKED (OK) | I5: ตกเบิกเดือนมกราคม 68
A6: 3 | B6: 1004213 | C6: =vlookup(B6,'Crew Data'!C:G,5,0) -> Worapada Suetrongmunkong | D6: 1 Febuary 2025 - 2 Febuary 2025 | E6: 2 | F6: =E6*400 -> 800 | G6: =COUNTIF(B:B,B6) -> 1 | H6: CHECKED (OK)
A7: 4 | B7: 1028736 | C7: =vlookup(B7,'Crew Data'!C:G,5,0) -> Nutchanat Tawong | D7: 1 Febuary 2025 - 2 Febuary 2025 | E7: 2 | F7: =E7*400 -> 800 | G7: =COUNTIF(B:B,B7) -> 1 | H7: CHECKED (OK)
A8: 5 | B8: 1007841 | C8: =vlookup(B8,'Crew Data'!C:G,5,0) -> Wisanee Nateeviriyaworakul | D8: 1 Febuary 2025 - 2 Febuary 2025 | E8: 2 | F8: =E8*400 -> 800 | G8: =COUNTIF(B:B,B8) -> 1 | H8: CHECKED (OK)
A9: 6 | B9: 1003418 | C9: =vlookup(B9,'Crew Data'!C:G,5,0) -> Chiravitch Kittiphongsathaporn | D9: 4 Febuary 2025 - 5 Febuary 2025 | E9: 2 | F9: =E9*400 -> 800 | G9: =COUNTIF(B:B,B9) -> 1 | H9: CHECKED (OK)
A10: 7 | B10: 1001614 | C10: =vlookup(B10,'Crew Data'!C:G,5,0) -> Sanlaya Kanrarat | D10: 6 Febuary 2025 - 7 Febuary 2025 | E10: 2 | F10: =E10*400 -> 800 | G10: =COUNTIF(B:B,B10) -> 1 | H10: CHECKED (OK)
A11: 8 | B11: 1012187 | C11: =vlookup(B11,'Crew Data'!C:G,5,0) -> Warangkana Mattaweewong | D11: 11 Febuary 2025 - 12 Febuary 2025 | E11: 2 | F11: =E11*400 -> 800 | G11: =COUNTIF(B:B,B11) -> 1 | H11: CHECKED (OK)
A12: 9 | B12: 1011844 | C12: =vlookup(B12,'Crew Data'!C:G,5,0) -> Thanyaporn Vaivattana | D12: 11 Febuary 2025 - 12 Febuary 2025 | E12: 2 | F12: =E12*400 -> 800 | G12: =COUNTIF(B:B,B12) -> 1 | H12: CHECKED (OK)
A13: 10 | B13: 1015405 | C13: =vlookup(B13,'Crew Data'!C:G,5,0) -> Nuttapon Pungjun | D13: 13 Febuary 2025 - 14 Febuary 2025 | E13: 2 | F13: =E13*400 -> 800 | G13: =COUNTIF(B:B,B13) -> 1 | H13: CHECKED (OK)
A14: 11 | B14: 1001286 | C14: =vlookup(B14,'Crew Data'!C:G,5,0) -> Sirinart Auypornbusyakom | D14: 11 Febuary 2025 - 12 Febuary 2025 | E14: 2 | F14: =E14*400 -> 800 | G14: =COUNTIF(B:B,B14) -> 1 | H14: CHECKED (OK)
A15: 12 | B15: 1011848 | C15: =vlookup(B15,'Crew Data'!C:G,5,0) -> Wiput Janvanichstaporn | D15: 15 Febuary 2025 - 16 Febuary 2025 | E15: 2 | F15: =E15*400 -> 800 | G15: =COUNTIF(B:B,B15) -> 1 | H15: CHECKED (OK)
A16: 13 | B16: 1014064 | C16: =vlookup(B16,'Crew Data'!C:G,5,0) -> Jaraspak Plengkhum | D16: 1 Febuary 2025 - 2 Febuary 2025 | E16: 2 | F16: =E16*400 -> 800 | G16: =COUNTIF(B:B,B16) -> 1 | H16: CHECKED (OK)
A17: 14 | B17: 1006995 | C17: =vlookup(B17,'Crew Data'!C:G,5,0) -> Kornrumpha Wongsing | D17: 15 Febuary 2025 - 16 Febuary 2025 | E17: 2 | F17: =E17*400 -> 800 | G17: =COUNTIF(B:B,B17) -> 1 | H17: CHECKED (OK)
... A44: 41 | B44: 1022662 | C44: =vlookup(B44,'Crew Data'!C:G,5,0) -> Wachiraporn Songkram | D44: 20 Febuary 2025 - 21 Febuary 2025 | E44: 2 | F44: =E44*400 -> 800 | G44: =COUNTIF(B:B,B44) -> 1 | H44: CHECKED (OK)
A45: 41 | C45: =vlookup(B45,'Crew Data'!C:G,5,0) -> #N/A | F45: =E45*400 -> 0 | G45: =COUNTIF(B:B,B45) -> 0 | H45: CHECKED (OK)
A46: 42 | C46: =vlookup(B46,'Crew Data'!C:G,5,0) -> #N/A | F46: =E46*400 -> 0 | G46: =COUNTIF(B:B,B46) -> 0 | H46: CHECKED (OK)
A47: 43 | C47: =vlookup(B47,'Crew Data'!C:G,5,0) -> #N/A | F47: =E47*400 -> 0 | G47: =COUNTIF(B:B,B47) -> 0 | H47: CHECKED (OK)
A48: 44 | C48: =vlookup(B48,'Crew Data'!C:G,5,0) -> #N/A | F48: =E48*400 -> 0 | G48: =COUNTIF(B:B,B48) -> 0 | H48: CHECKED (OK)
A49: 45 | C49: =vlookup(B49,'Crew Data'!C:G,5,0) -> #N/A | F49: =E49*400 -> 0 | G49: =COUNTIF(B:B,B49) -> 0 | H49: CHECKED (OK)
A50: 46 | C50: =vlookup(B50,'Crew Data'!C:G,5,0) -> #N/A | F50: =E50*400 -> 0 | G50: =COUNTIF(B:B,B50) -> 0 | H50: CHECKED (OK)
A51: 47 | C51: =vlookup(B51,'Crew Data'!C:G,5,0) -> #N/A | F51: =E51*400 -> 0 | G51: =COUNTIF(B:B,B51) -> 0 | H51: CHECKED (OK)
A52: 48 | C52: =vlookup(B52,'Crew Data'!C:G,5,0) -> #N/A | F52: =E52*400 -> 0 | G52: =COUNTIF(B:B,B52) -> 0 | H52: CHECKED (OK)
A53: 49 | C53: =vlookup(B53,'Crew Data'!C:G,5,0) -> #N/A | F53: =E53*400 -> 0 | G53: =COUNTIF(B:B,B53) -> 0 | H53: CHECKED (OK)
A54: 50 | C54: =vlookup(B54,'Crew Data'!C:G,5,0) -> #N/A | F54: =E54*400 -> 0 | G54: =COUNTIF(B:B,B54) -> 0 | H54: CHECKED (OK)

Sheet MARCH 2025
A1: Perdiem Report in MARCH 2025 | H1: Last updated : 2 APR 2025 Time: 10.00 (Status : CLOSE)
A2: Item | B2: New ID No. | C2: Employee name | D2: Period | E2: Description
E3: Days | F3: Total Perdiem (THB) | H3: Cross Checked by Supervisor | I3: REMARK
A4: 1 | B4: 1001617 | C4: =vlookup(B4,'Crew Data'!C:G,5,0) -> Suthida Tanakarn | D4: 13 FEB 2025 - 14 FEB 2025 | E4: 2 | F4: =E4*400 -> 800 | G4: =COUNTIF(B:B,B4) -> 1 | H4: CHECKED (OK) | I4: ตกเบิกเดือนกุมภาพันธ์
A5: 2 | B5: 1007022 | C5: =vlookup(B5,'Crew Data'!C:G,5,0) -> Waroot Chanpueak | D5: 1 March 2025 - 2 March 2025 | E5: 2 | F5: =E5*400 -> 800 | G5: =COUNTIF(B:B,B5) -> 1 | H5: CHECKED (OK)
A6: 3 | B6: 1015094 | C6: =vlookup(B6,'Crew Data'!C:G,5,0) -> Pheephat Janjamras | D6: 1 March 2025 - 2 March 2025 | E6: 2 | F6: =E6*400 -> 800 | G6: =COUNTIF(B:B,B6) -> 1 | H6: CHECKED (OK)
A7: 4 | B7: 1010880 | C7: =vlookup(B7,'Crew Data'!C:G,5,0) -> Chutima Thitisantikhun | D7: 1 March 2025 - 2 March 2025 | E7: 2 | F7: =E7*400 -> 800 | G7: =COUNTIF(B:B,B7) -> 1 | H7: CHECKED (OK)
A8: 5 | B8: 1043868 | C8: =vlookup(B8,'Crew Data'!C:G,5,0) -> Sutida Srisuwantada | D8: 4 March 2025 - 5 March 2025 | E8: 2 | F8: =E8*400 -> 800 | G8: =COUNTIF(B:B,B8) -> 1 | H8: CHECKED (OK)
A9: 6 | B9: 1009434 | C9: =vlookup(B9,'Crew Data'!C:G,5,0) -> Wanpiya Kaewyok | D9: 1 March 2025 - 2 March 2025 | E9: 2 | F9: =E9*400 -> 800 | G9: =COUNTIF(B:B,B9) -> 1 | H9: CHECKED (OK)
A10: 7 | B10: 1005303 | C10: =vlookup(B10,'Crew Data'!C:G,5,0) -> Piyathida Jaikla | D10: 8 March 2025 - 9 March 2025 | E10: 2 | F10: =E10*400 -> 800 | G10: =COUNTIF(B:B,B10) -> 1 | H10: CHECKED (OK)
A11: 8 | B11: 1005289 | C11: =vlookup(B11,'Crew Data'!C:G,5,0) -> Varoonyupa Choovet | D11: 8 March 2025 - 9 March 2025 | E11: 2 | F11: =E11*400 -> 800 | G11: =COUNTIF(B:B,B11) -> 1 | H11: CHECKED (OK)
A12: 9 | B12: 1019402 | C12: =vlookup(B12,'Crew Data'!C:G,5,0) -> Methawat Thitinawasup | D12: 13 March 2025 - 14 March 2025 | E12: 2 | F12: =E12*400 -> 800 | G12: =COUNTIF(B:B,B12) -> 1 | H12: CHECKED (OK)
A13: 10 | B13: 1010805 | C13: =vlookup(B13,'Crew Data'!C:G,5,0) -> Tipparada Chiewsamran | D13: 8 March 2025 - 9 March 2025 | E13: 2 | F13: =E13*400 -> 800 | G13: =COUNTIF(B:B,B13) -> 1 | H13: CHECKED (OK)
A14: 11 | B14: 1000736 | C14: =vlookup(B14,'Crew Data'!C:G,5,0) -> Ekkachai Moolla | D14: 13 March 2025 - 14 March 2025 | E14: 2 | F14: =E14*400 -> 800 | G14: =COUNTIF(B:B,B14) -> 1 | H14: CHECKED (OK)
A15: 12 | B15: 1010721 | C15: =vlookup(B15,'Crew Data'!C:G,5,0) -> Papitchaya Saytasuhat | D15: 18 March 2025 - 19 March 2025 | E15: 2 | F15: =E15*400 -> 800 | G15: =COUNTIF(B:B,B15) -> 1 | H15: CHECKED (OK)
A16: 13 | B16: 1003302 | C16: =vlookup(B16,'Crew Data'!C:G,5,0) -> Panwad Thongkham | D16: 8 March 2025 - 9 March 2025 | E16: 2 | F16: =E16*400 -> 800 | G16: =COUNTIF(B:B,B16) -> 1 | H16: CHECKED (OK)
... A40: 37 | B40: 1003047 | C40: =vlookup(B40,'Crew Data'!C:G,5,0) -> Mananpat Dechanoppawit | D40: 29 March 2025 - 30 March 2025 | E40: 2 | F40: =E40*400 -> 800 | G40: =COUNTIF(B:B,B40) -> 1 | H40: CHECKED (OK)

Sheet APRIL 2025
A1: Perdiem Report in April 2025 | I1: Last updated : 3 MAY 2025 Time: 10.00 (Status : CLOSE)
A2: Item | B2: New ID No. | C2: Employee name | D2: Period | E2: Description
E3: Days | F3: Total Perdiem (THB) | H3: Cross Checked by Supervisor | I3: REMARK
A4: 1 | B4: 1013189 | C4: =vlookup(B4,'Crew Data'!C:G,5,0) -> Supakrit Khongvittaya | D4: 15 March 2025 - 16 March 2025 | E4: 2 | F4: =E4*400 -> 800 | G4: =COUNTIF(B:B,B4) -> 1 | H4: CHECKED (OK) | I4: ตกเบิกเดือนมีนาคม
A5: 2 | B5: 1004683 | C5: =vlookup(B5,'Crew Data'!C:G,5,0) -> Prok Lartham | D5: 1 March 2025 - 31 March 2025 | E5: 31 | F5: =E5*400 -> 12400 | G5: =COUNTIF(B:B,B5) -> 1 | H5: CHECKED (OK) | I5: ตกเบิกเดือนมีนาคม
A6: 3 | B6: 1012193 | C6: =vlookup(B6,'Crew Data'!C:G,5,0) -> Phoemsakun Phongpradist | D6: 13 March 2025 - 14 March 2025 | E6: 2 | F6: =E6*400 -> 800 | G6: =COUNTIF(B:B,B6) -> 1 | H6: CHECKED (OK) | I6: ตกเบิกเดือนมีนาคม
A7: 4 | B7: 1005762 | C7: =vlookup(B7,'Crew Data'!C:G,5,0) -> Photchara Srisuk | D7: 1 March 2025 - 7 March 2025 15 MARCH 2025 - 31 MARCH 2025 | E7: 24 | F7: =E7*400 -> 9600 | G7: =COUNTIF(B:B,B7) -> 1 | H7: CHECKED (OK) | I7: ตกเบิกเดือนมีนาคม
A8: 5 | B8: 1012975 | C8: =vlookup(B8,'Crew Data'!C:G,5,0) -> Chalintara Chinaratana | D8: 22 March 2025 - 23 March 2025 | E8: 2 | F8: =E8*400 -> 800 | G8: =COUNTIF(B:B,B8) -> 1 | H8: CHECKED (OK) | I8: ตกเบิกเดือนมีนาคม
A9: 6 | B9: 1007207 | C9: =vlookup(B9,'Crew Data'!C:G,5,0) -> Sasiwan Nakate | D9: 8 Feb 2025 - 9 Feb 2025 20 March 2025 - 21 March 2025 23 April 2025 - 24 April 2025 | E9: 6 | F9: =E9*400 -> 2400 | G9: =COUNTIF(B:B,B9) -> 1 | H9: CHECKED (OK)
A10: 7 | B10: 1011844 | C10: =vlookup(B10,'Crew Data'!C:G,5,0) -> Thanyaporn Vaivattana | D10: 3 April 2025 - 4 April 2025 | E10: 2 | F10: =E10*400 -> 800 | G10: =COUNTIF(B:B,B10) -> 1 | H10: CHECKED (OK)
A11: 8 | B11: 1005769 | C11: =vlookup(B11,'Crew Data'!C:G,5,0) -> Thanicha Noodee | D11: 5 April 2025 - 6 April 2025 | E11: 2 | F11: =E11*400 -> 800 | G11: =COUNTIF(B:B,B11) -> 1 | H11: CHECKED (OK)
A12: 9 | B12: 1002202 | C12: =vlookup(B12,'Crew Data'!C:G,5,0) -> Nithipkan Damrongpongkhajorn | D12: 5 April 2025 - 6 April 2025 | E12: 2 | F12: =E12*400 -> 800 | G12: =COUNTIF(B:B,B12) -> 1 | H12: CHECKED (OK)
A13: 10 | B13: 1012368 | C13: =vlookup(B13,'Crew Data'!C:G,5,0) -> #N/A | D13: 10 April 2025 - 11 April 2025 | E13: 2 | F13: =E13*400 -> 800 | G13: =COUNTIF(B:B,B13) -> 1 | H13: CHECKED (OK)
A14: 11 | B14: 1004292 | C14: =vlookup(B14,'Crew Data'!C:G,5,0) -> Darunee Anumat | D14: 5 April 2025 - 6 April 2025 | E14: 2 | F14: =E14*400 -> 800 | G14: =COUNTIF(B:B,B14) -> 1 | H14: CHECKED (OK)
A15: 12 | B15: 1014665 | C15: =vlookup(B15,'Crew Data'!C:G,5,0) -> Jaruwan Charoenratanapirom | D15: 12 April 2025 - 13 April 2025 | E15: 2 | F15: =E15*400 -> 800 | G15: =COUNTIF(B:B,B15) -> 1 | H15: CHECKED (OK)
A16: 13 | B16: 1011513 | C16: =vlookup(B16,'Crew Data'!C:G,5,0) -> Rawitnat Marayat | D16: 12 April 2025 - 13 April 2025 | E16: 2 | F16: =E16*400 -> 800 | G16: =COUNTIF(B:B,B16) -> 1 | H16: CHECKED (OK)
A17: 14 | B17: 1010904 | C17: =vlookup(B17,'Crew Data'!C:G,5,0) -> Phadoongkiat Phanwilai | D17: 12 April 2025 - 13 April 2025 | E17: 2 | F17: =E17*400 -> 800 | G17: =COUNTIF(B:B,B17) -> 1 | H17: CHECKED (OK)
A18: 15 | B18: 1014662 | C18: =vlookup(B18,'Crew Data'!C:G,5,0) -> Duangkamon Wongjareanyong | D18: 11 April 2025 - 12 April 2025 | E18: 2 | F18: =E18*400 -> 800 | G18: =COUNTIF(B:B,B18) -> 1 | H18: CHECKED (OK)
A19: 16 | B19: 1005444 | C19: =vlookup(B19,'Crew Data'!C:G,5,0) -> Rassarin Weerathammavit | D19: 10 April 2025 - 11 April 2025 | E19: 2 | F19: =E19*400 -> 800 | G19: =COUNTIF(B:B,B19) -> 1 | H19: CHECKED (OK)
A20: 17 | B20: 1016385 | C20: =vlookup(B20,'Crew Data'!C:G,5,0) -> Raweewan Sritong | D20: 12 April 2025 - 13 April 2025 | E20: 2 | F20: =E20*400 -> 800 | G20: =COUNTIF(B:B,B20) -> 1 | H20: CHECKED (OK)
... A61: 58 | B61: 1005824 | C61: =vlookup(B61,'Crew Data'!C:G,5,0) -> Panchita Swangarom | D61: 16 April 2025 - 17 April 2025 | E61: 2 | F61: =E61*400 -> 800 | G61: =COUNTIF(B:B,B61) -> 1 | H61: CHECKED (OK)
A62: 59 | B62: 1012902 | C62: =vlookup(B62,'Crew Data'!C:G,5,0) -> Saowarat Sowa | D62: 45777 | E62: 1 | F62: =E62*400 -> 400 | G62: =COUNTIF(B:B,B62) -> 1 | H62: CHECKED (OK)
A63: 60 | B63: 1006995 | C63: =vlookup(B63,'Crew Data'!C:G,5,0) -> Kornrumpha Wongsing | D63: 27 April 2025 - 28 April 2025 | E63: 2 | F63: =E63*400 -> 800 | G63: =COUNTIF(B:B,B63) -> 1 | H63: CHECKED (OK)
A64: 61 | B64: 1009001 | C64: =vlookup(B64,'Crew Data'!C:G,5,0) -> Suphachok Pannakitchakul | D64: 1 April 2025 - 30 April 2025 | E64: 30 | F64: =E64*400 -> 12000 | G64: =COUNTIF(B:B,B64) -> 1 | H64: CHECKED (OK)
A65: 62 | B65: 1025144 | C65: =vlookup(B65,'Crew Data'!C:G,5,0) -> Maythawee Krabuansri | D65: 10 April 2025 - 11 April 2025 | E65: 2 | F65: =E65*400 -> 800 | G65: =COUNTIF(B:B,B65) -> 1 | H65: CHECKED (OK)
A66: 63 | B66: 1002909 | C66: =vlookup(B66,'Crew Data'!C:G,5,0) -> Panodpol Yensuong | D66: 16 April 2025 - 17 April 2025 | E66: 2 | F66: =E66*400 -> 800 | G66: =COUNTIF(B:B,B66) -> 1 | H66: CHECKED (OK)
A67: 64 | B67: 1040354 | C67: =vlookup(B67,'Crew Data'!C:G,5,0) -> #N/A | D67: 18 April 2025 - 19 April 2025 | E67: 2 | F67: =E67*400 -> 800 | G67: =COUNTIF(B:B,B67) -> 1 | H67: CHECKED (OK)
A68: 65 | B68: 1006844 | C68: =vlookup(B68,'Crew Data'!C:G,5,0) -> Rada Nilyam | D68: 15 April 2025 - 16 April 2025 | E68: 2 | F68: =E68*400 -> 800 | G68: =COUNTIF(B:B,B68) -> 1 | H68: CHECKED (OK)
A69: 66 | B69: 1012369 | C69: =vlookup(B69,'Crew Data'!C:G,5,0) -> Savitree Sukprakop | D69: 15 April 2025 - 16 April 2025 | E69: 2 | F69: =E69*400 -> 800 | G69: =COUNTIF(B:B,B69) -> 1 | H69: CHECKED (OK)
A70: 67 | B70: 1044217 | C70: =vlookup(B70,'Crew Data'!C:G,5,0) -> Tanayaporn Sombatboriboon | D70: 45777 | E70: 1 | F70: =E70*400 -> 400 | G70: =COUNTIF(B:B,B70) -> 1 | H70: CHECKED (OK)
E71: Total | F71: =sum(F4:F70) -> 150800

Sheet MAY 2025
A1: Perdiem Report in May 2025 | I1: Last updated : 4 JUN 2025 Time: 10.00 (Status : CLOSE)
A2: Item | B2: New ID No. | C2: Employee name | D2: Period | E2: Description
E3: Days | F3: Total Perdiem (THB) | H3: Cross Checked by Supervisor | I3: REMARK
A4: 1 | B4: 1040506 | C4: =vlookup(B4,'Crew Data'!C:G,5,0) -> Chomphunut Detdutsadee | D4: 10 April 2025 - 11 April 2025 28 May 2025 - 29 May 2025 | E4: 4 | F4: =E4*400 -> 1600 | G4: =COUNTIF(B:B,B4) -> 1 | H4: CHECKED (OK) | I4: ตกเบิกเดือนเมษายน
A5: 2 | B5: 1002910 | C5: =vlookup(B5,'Crew Data'!C:G,5,0) -> Patsita Patchararujirathchot | D5: 1 April 2025 - 26 April 2025 28 April 2025 | E5: 27 | F5: =E5*400 -> 10800 | G5: =COUNTIF(B:B,B5) -> 1 | H5: CHECKED (OK) | I5: ตกเบิกเดือนเมษายน
